Workbook

Sheet Инструкция
A1: Как работать с шаблоном бюджета закупок
A2: Татьяна Бандюк · tatsianabandziuk.com
A4: До сезона
A5: 1. План продаж | B5: Внесите план продаж по месяцам для каждого рынка и категории на листе OTB. Отправная точка — продажи тех же недель прошлого сезона.
A6: 2. План остатков и уценки | B6: Внесите план уценки и остаток, который нужен на конец каждого месяца. Остаток на начало вносится только для первого месяца, дальше его считает формула.
A7: 3. Бюджет | B7: Внесите уже размещённые заказы, маржинальность закупки и среднюю себестоимость единицы. Лист покажет open-to-buy в рознице, по себестоимости и в штуках.
A8: 4. Заказы | B8: Разложите штуки по размерам и цветам на листе «Размеры и цвета», разместите заказы и добавьте их в строку «Заказано».
A9: В течение сезона
A10: 5. Сверка с фактом | B10: Когда месяц закрыт, внесите фактические продажи и поставки и увеличьте номер текущего месяца. Перед следующим заказом откройте лист «Проверки».
A11: 6. Новый прогноз | B11: Если продажи ушли от плана, сначала измените план продаж и уценки на оставшиеся месяцы, потом снова смотрите на open-to-buy.
A12: Передача модели команде
A13: Владельцы | B13: У каждого показателя есть владелец на листе «Определения». Согласуйте имена до начала сезона.
A14: Изменения | B14: Новый рынок или категория: скопируйте полный блок из 13 строк под последним и поменяйте названия. Блок «Все рынки» учтёт его автоматически.
A15: Обозначения | B15: Жёлтая ячейка — ввод. Белая — формула. Зелёный заголовок — раздел. Значения в примере условные, замените их своими.

Sheet OTB
A1: Бюджет закупок open-to-buy по месяцам, категориям и рынкам
A2: Жёлтые ячейки — ввод данных. Белые — формулы, их не перезаписывайте. Все суммы в розничных ценах, если в строке не сказано о себестоимости или штуках.
A4: Сезон | C4: ВЛ27
A5: Валюта | C5: EUR
A6: Текущий месяц (1–6) | C6: 2
A7: Допустимое отклонение | C7: 0.1
C10: Месяцы | D10: 1 | E10: 2 | F10: 3 | G10: 4 | H10: 5 | I10: 6
A11: Рынок | B11: Категория | C11: Строка | D11: фев | E11: мар | F11: апр | G11: май | H11: июн | I11: июл | J11: Итого за сезон
A13: Все рынки | B13: Все категории | C13: План продаж | D13: =SUMIF($C$26:$C$400,$C13,D$26:D$400) | E13: =SUMIF($C$26:$C$400,$C13,E$26:E$400) | F13: =SUMIF($C$26:$C$400,$C13,F$26:F$400) | G13: =SUMIF($C$26:$C$400,$C13,G$26:G$400) | H13: =SUMIF($C$26:$C$400,$C13,H$26:H$400) | I13: =SUMIF($C$26:$C$400,$C13,I$26:I$400) | J13: =SUM(D13:I13)
C14: План уценки | D14: =SUMIF($C$26:$C$400,$C14,D$26:D$400) | E14: =SUMIF($C$26:$C$400,$C14,E$26:E$400) | F14: =SUMIF($C$26:$C$400,$C14,F$26:F$400) | G14: =SUMIF($C$26:$C$400,$C14,G$26:G$400) | H14: =SUMIF($C$26:$C$400,$C14,H$26:H$400) | I14: =SUMIF($C$26:$C$400,$C14,I$26:I$400) | J14: =SUM(D14:I14)
C15: План остатка на конец | D15: =SUMIF($C$26:$C$400,$C15,D$26:D$400) | E15: =SUMIF($C$26:$C$400,$C15,E$26:E$400) | F15: =SUMIF($C$26:$C$400,$C15,F$26:F$400) | G15: =SUMIF($C$26:$C$400,$C15,G$26:G$400) | H15: =SUMIF($C$26:$C$400,$C15,H$26:H$400) | I15: =SUMIF($C$26:$C$400,$C15,I$26:I$400) | J15: =I15
C16: Остаток на начало | D16: =SUMIF($C$26:$C$400,$C16,D$26:D$400) | E16: =SUMIF($C$26:$C$400,$C16,E$26:E$400) | F16: =SUMIF($C$26:$C$400,$C16,F$26:F$400) | G16: =SUMIF($C$26:$C$400,$C16,G$26:G$400) | H16: =SUMIF($C$26:$C$400,$C16,H$26:H$400) | I16: =SUMIF($C$26:$C$400,$C16,I$26:I$400) | J16: =D16
C17: Заказано | D17: =SUMIF($C$26:$C$400,$C17,D$26:D$400) | E17: =SUMIF($C$26:$C$400,$C17,E$26:E$400) | F17: =SUMIF($C$26:$C$400,$C17,F$26:F$400) | G17: =SUMIF($C$26:$C$400,$C17,G$26:G$400) | H17: =SUMIF($C$26:$C$400,$C17,H$26:H$400) | I17: =SUMIF($C$26:$C$400,$C17,I$26:I$400) | J17: =SUM(D17:I17)
C18: Open-to-buy | D18: =SUMIF($C$26:$C$400,$C18,D$26:D$400) | E18: =SUMIF($C$26:$C$400,$C18,E$26:E$400) | F18: =SUMIF($C$26:$C$400,$C18,F$26:F$400) | G18: =SUMIF($C$26:$C$400,$C18,G$26:G$400) | H18: =SUMIF($C$26:$C$400,$C18,H$26:H$400) | I18: =SUMIF($C$26:$C$400,$C18,I$26:I$400) | J18: =SUM(D18:I18)
C19: Маржинальность закупки % | D19: =IF(D18=0,"",1-D20/D18) | E19: =IF(E18=0,"",1-E20/E18) | F19: =IF(F18=0,"",1-F20/F18) | G19: =IF(G18=0,"",1-G20/G18) | H19: =IF(H18=0,"",1-H20/H18) | I19: =IF(I18=0,"",1-I20/I18) | J19: =IF(J18=0,"",1-J20/J18)
C20: Open-to-buy по себестоимости | D20: =SUMIF($C$26:$C$400,$C20,D$26:D$400) | E20: =SUMIF($C$26:$C$400,$C20,E$26:E$400) | F20: =SUMIF($C$26:$C$400,$C20,F$26:F$400) | G20: =SUMIF($C$26:$C$400,$C20,G$26:G$400) | H20: =SUMIF($C$26:$C$400,$C20,H$26:H$400) | I20: =SUMIF($C$26:$C$400,$C20,I$26:I$400) | J20: =SUM(D20:I20)
C21: Средняя себестоимость единицы | D21: =IF(D22=0,"",D20/D22) | E21: =IF(E22=0,"",E20/E22) | F21: =IF(F22=0,"",F20/F22) | G21: =IF(G22=0,"",G20/G22) | H21: =IF(H22=0,"",H20/H22) | I21: =IF(I22=0,"",I20/I22)
C22: Open-to-buy в штуках | D22: =SUMIF($C$26:$C$400,$C22,D$26:D$400) | E22: =SUMIF($C$26:$C$400,$C22,E$26:E$400) | F22: =SUMIF($C$26:$C$400,$C22,F$26:F$400) | G22: =SUMIF($C$26:$C$400,$C22,G$26:G$400) | H22: =SUMIF($C$26:$C$400,$C22,H$26:H$400) | I22: =SUMIF($C$26:$C$400,$C22,I$26:I$400) | J22: =SUM(D22:I22)
C23: Продажи факт | D23: =SUMIF($C$26:$C$400,$C23,D$26:D$400) | E23: =SUMIF($C$26:$C$400,$C23,E$26:E$400) | F23: =SUMIF($C$26:$C$400,$C23,F$26:F$400) | G23: =SUMIF($C$26:$C$400,$C23,G$26:G$400) | H23: =SUMIF($C$26:$C$400,$C23,H$26:H$400) | I23: =SUMIF($C$26:$C$400,$C23,I$26:I$400) | J23: =SUM(D23:I23)
C24: Поставки факт | D24: =SUMIF($C$26:$C$400,$C24,D$26:D$400) | E24: =SUMIF($C$26:$C$400,$C24,E$26:E$400) | F24: =SUMIF($C$26:$C$400,$C24,F$26:F$400) | G24: =SUMIF($C$26:$C$400,$C24,G$26:G$400) | H24: =SUMIF($C$26:$C$400,$C24,H$26:H$400) | I24: =SUMIF($C$26:$C$400,$C24,I$26:I$400) | J24: =SUM(D24:I24)
C25: Проверка | D25: =IF(COUNTIF(D$26:D$400,"Перезакуп")>0,"Перезакуп",IF(COUNTIF(D$26:D$400,"Внесите факт")>0,"Внесите факт",IF(COUNTIF(D$26:D$400,"Продажи вне плана")>0,"Продажи вне плана",IF(D$10>$C$6,"","OK")))) | E25: =IF(COUNTIF(E$26:E$400,"Перезакуп")>0,"Перезакуп",IF(COUNTIF(E$26:E$400,"Внесите факт")>0,"Внесите факт",IF(COUNTIF(E$26:E$400,"Продажи вне плана")>0,"Продажи вне плана",IF(E$10>$C$6,"","OK")))) | F25: =IF(COUNTIF(F$26:F$400,"Перезакуп")>0,"Перезакуп",IF(COUNTIF(F$26:F$400,"Внесите факт")>0,"Внесите факт",IF(COUNTIF(F$26:F$400,"Продажи вне плана")>0,"Продажи вне плана",IF(F$10>$C$6,"","OK")))) | G25: =IF(COUNTIF(G$26:G$400,"Перезакуп")>0,"Перезакуп",IF(COUNTIF(G$26:G$400,"Внесите факт")>0,"Внесите факт",IF(COUNTIF(G$26:G$400,"Продажи вне плана")>0,"Продажи вне плана",IF(G$10>$C$6,"","OK")))) | H25: =IF(COUNTIF(H$26:H$400,"Перезакуп")>0,"Перезакуп",IF(COUNTIF(H$26:H$400,"Внесите факт")>0,"Внесите факт",IF(COUNTIF(H$26:H$400,"Продажи вне плана")>0,"Продажи вне плана",IF(H$10>$C$6,"","OK")))) | I25: =IF(COUNTIF(I$26:I$400,"Перезакуп")>0,"Перезакуп",IF(COUNTIF(I$26:I$400,"Внесите факт")>0,"Внесите факт",IF(COUNTIF(I$26:I$400,"Продажи вне плана")>0,"Продажи вне плана",IF(I$10>$C$6,"","OK"))))
A26: Рынок A | B26: Платья | C26: План продаж | D26: 42000 | E26: 48000 | F26: 55000 | G26: 60000 | H26: 52000 | I26: 38000 | J26: =SUM(D26:I26)
C27: План уценки | D27: 1500 | E27: 1800 | F27: 2500 | G27: 4000 | H27: 9000 | I27: 12000 | J27: =SUM(D27:I27)
C28: План остатка на конец | D28: 120000 | E28: 130000 | F28: 125000 | G28: 110000 | H28: 80000 | I28: 50000 | J28: =I28
C29: Остаток на начало | D29: 110000 | E29: =D28 | F29: =E28 | G29: =F28 | H29: =G28 | I29: =H28 | J29: =D29
C30: Заказано | D30: 30000 | E30: 40000 | F30: 35000 | G30: 20000 | H30: 10000 | I30: 0 | J30: =SUM(D30:I30)
C31: Open-to-buy | D31: =D26+D27+D28-D29-D30 | E31: =E26+E27+E28-E29-E30 | F31: =F26+F27+F28-F29-F30 | G31: =G26+G27+G28-G29-G30 | H31: =H26+H27+H28-H29-H30 | I31: =I26+I27+I28-I29-I30 | J31: =SUM(D31:I31)
C32: Маржинальность закупки % | D32: 0.62 | E32: =D32 | F32: =E32 | G32: =F32 | H32: =G32 | I32: =H32 | J32: =IF(J31=0,"",1-J33/J31)
C33: Open-to-buy по себестоимости | D33: =D31*(1-D32) | E33: =E31*(1-E32) | F33: =F31*(1-F32) | G33: =G31*(1-G32) | H33: =H31*(1-H32) | I33: =I31*(1-I32) | J33: =SUM(D33:I33)
C34: Средняя себестоимость единицы | D34: 24 | E34: =D34 | F34: =E34 | G34: =F34 | H34: =G34 | I34: =H34
C35: Open-to-buy в штуках | D35: =IF(D34>0,ROUND(D33/D34,0),0) | E35: =IF(E34>0,ROUND(E33/E34,0),0) | F35: =IF(F34>0,ROUND(F33/F34,0),0) | G35: =IF(G34>0,ROUND(G33/G34,0),0) | H35: =IF(H34>0,ROUND(H33/H34,0),0) | I35: =IF(I34>0,ROUND(I33/I34,0),0) | J35: =SUM(D35:I35)
C36: Продажи факт | D36: 40500 | E36: 51000 | J36: =SUM(D36:I36)
C37: Поставки факт | D37: 29000 | E37: 41500 | J37: =SUM(D37:I37)
C38: Проверка | D38: =IF(D31<0,"Перезакуп",IF(D$10>$C$6,"",IF(OR(D36="",D37=""),"Внесите факт",IF(AND(D26>0,ABS(D36/D26-1)>$C$7),"Продажи вне плана","OK")))) | E38: =IF(E31<0,"Перезакуп",IF(E$10>$C$6,"",IF(OR(E36="",E37=""),"Внесите факт",IF(AND(E26>0,ABS(E36/E26-1)>$C$7),"Продажи вне плана","OK")))) | F38: =IF(F31<0,"Перезакуп",IF(F$10>$C$6,"",IF(OR(F36="",F37=""),"Внесите факт",IF(AND(F26>0,ABS(F36/F26-1)>$C$7),"Продажи вне плана","OK")))) | G38: =IF(G31<0,"Перезакуп",IF(G$10>$C$6,"",IF(OR(G36="",G37=""),"Внесите факт",IF(AND(G26>0,ABS(G36/G26-1)>$C$7),"Продажи вне плана","OK")))) | H38: =IF(H31<0,"Перезакуп",IF(H$10>$C$6,"",IF(OR(H36="",H37=""),"Внесите факт",IF(AND(H26>0,ABS(H36/H26-1)>$C$7),"Продажи вне плана","OK")))) | I38: =IF(I31<0,"Перезакуп",IF(I$10>$C$6,"",IF(OR(I36="",I37=""),"Внесите факт",IF(AND(I26>0,ABS(I36/I26-1)>$C$7),"Продажи вне плана","OK"))))
A39: Рынок A | B39: Трикотаж | C39: План продаж | D39: 26000 | E39: 24000 | F39: 18000 | G39: 12000 | H39: 9000 | I39: 7000 | J39: =SUM(D39:I39)
C40: План уценки | D40: 1000 | E40: 1500 | F40: 2500 | G40: 3500 | H40: 3000 | I40: 2500 | J40: =SUM(D40:I40)
C41: План остатка на конец | D41: 70000 | E41: 60000 | F41: 45000 | G41: 30000 | H41: 20000 | I41: 12000 | J41: =I41
C42: Остаток на начало | D42: 75000 | E42: =D41 | F42: =E41 | G42: =F41 | H42: =G41 | I42: =H41 | J42: =D42
C43: Заказано | D43: 15000 | E43: 8000 | F43: 5000 | G43: 0 | H43: 0 | I43: 0 | J43: =SUM(D43:I43)
C44: Open-to-buy | D44: =D39+D40+D41-D42-D43 | E44: =E39+E40+E41-E42-E43 | F44: =F39+F40+F41-F42-F43 | G44: =G39+G40+G41-G42-G43 | H44: =H39+H40+H41-H42-H43 | I44: =I39+I40+I41-I42-I43 | J44: =SUM(D44:I44)
...

Sheet Проверки
A1: Три проверки, которые не дают бюджету разойтись с фактом
A2: Число отмеченных месяцев по каждому блоку. Всё, что больше нуля, требует решения до следующего заказа.
A4: Рынок | B4: Категория | C4: Месяцы с перезакупом | D4: Факт не внесён | E4: Продажи вне плана | F4: Статус
A5: =OTB!A26 | B5: =OTB!B26 | C5: =COUNTIF(OTB!D38:I38,"Перезакуп") | D5: =COUNTIF(OTB!D38:I38,"Внесите факт") | E5: =COUNTIF(OTB!D38:I38,"Продажи вне плана") | F5: =IF(SUM(C5:E5)=0,"OK","Разобрать")
A6: =OTB!A39 | B6: =OTB!B39 | C6: =COUNTIF(OTB!D51:I51,"Перезакуп") | D6: =COUNTIF(OTB!D51:I51,"Внесите факт") | E6: =COUNTIF(OTB!D51:I51,"Продажи вне плана") | F6: =IF(SUM(C6:E6)=0,"OK","Разобрать")
A7: =OTB!A52 | B7: =OTB!B52 | C7: =COUNTIF(OTB!D64:I64,"Перезакуп") | D7: =COUNTIF(OTB!D64:I64,"Внесите факт") | E7: =COUNTIF(OTB!D64:I64,"Продажи вне плана") | F7: =IF(SUM(C7:E7)=0,"OK","Разобрать")
A8: =OTB!A65 | B8: =OTB!B65 | C8: =COUNTIF(OTB!D77:I77,"Перезакуп") | D8: =COUNTIF(OTB!D77:I77,"Внесите факт") | E8: =COUNTIF(OTB!D77:I77,"Продажи вне плана") | F8: =IF(SUM(C8:E8)=0,"OK","Разобрать")
A9: Все рынки | B9: Все категории | C9: =SUM(C5:C8) | D9: =SUM(D5:D8) | E9: =SUM(E5:E8) | F9: =IF(SUM(C9:E9)=0,"OK","Разобрать")
A11: Перезакуп | B11: Open-to-buy меньше нуля: заказы и плановый остаток уже больше, чем нужно месяцу. Отмените, перенесите или разнесите заказы по месяцам.
A12: Внесите факт | B12: В закрытом месяце нет фактических продаж или поставок. План нельзя проверить, пока не внесены обе цифры.
A13: Продажи вне плана | B13: Фактические продажи отличаются от плана больше, чем на допустимое отклонение. Сначала пересчитайте прогноз на оставшиеся месяцы, потом закупайте.

Sheet Размеры и цвета
A1: Размерные и цветовые доли по очищенным продажам
A2: Берите продажи за недели, когда в наличии были все размеры: так распроданный размер не выглядит непопулярным. Закупка делится по полученным долям.
A4: Категория | B4: =OTB!B26
A5: Штук к закупке | B5: =OTB!J35
A7: Размер | B7: Очищенные продажи, шт. | C7: Доля | D7: Штук к закупке
A8: XS | B8: 90 | C8: =IF(SUM($B$8:$B$12)=0,0,B8/SUM($B$8:$B$12)) | D8: =ROUND($B$5*C8,0)
A9: S | B9: 260 | C9: =IF(SUM($B$8:$B$12)=0,0,B9/SUM($B$8:$B$12)) | D9: =ROUND($B$5*C9,0)
A10: M | B10: 340 | C10: =IF(SUM($B$8:$B$12)=0,0,B10/SUM($B$8:$B$12)) | D10: =ROUND($B$5*C10,0)
A11: L | B11: 220 | C11: =IF(SUM($B$8:$B$12)=0,0,B11/SUM($B$8:$B$12)) | D11: =ROUND($B$5*C11,0)
A12: XL | B12: 90 | C12: =IF(SUM($B$8:$B$12)=0,0,B12/SUM($B$8:$B$12)) | D12: =ROUND($B$5*C12,0)
A13: Итого | B13: =SUM(B8:B12) | C13: =SUM(C8:C12) | D13: =SUM(D8:D12)
A15: Цвет | B15: Очищенные продажи, шт. | C15: Доля | D15: Штук к закупке
A16: Чёрный | B16: 420 | C16: =IF(SUM($B$16:$B$19)=0,0,B16/SUM($B$16:$B$19)) | D16: =ROUND($B$5*C16,0)
A17: Тёмно-синий | B17: 260 | C17: =IF(SUM($B$16:$B$19)=0,0,B17/SUM($B$16:$B$19)) | D17: =ROUND($B$5*C17,0)
A18: Бежевый | B18: 190 | C18: =IF(SUM($B$16:$B$19)=0,0,B18/SUM($B$16:$B$19)) | D18: =ROUND($B$5*C18,0)
A19: Другие | B19: 130 | C19: =IF(SUM($B$16:$B$19)=0,0,B19/SUM($B$16:$B$19)) | D19: =ROUND($B$5*C19,0)
A20: Итого | B20: =SUM(B16:B19) | C20: =SUM(C16:C19) | D20: =SUM(D16:D19)
A22: После округления сумма может отличаться на одну-две штуки: поправьте самый большой размер.

Sheet Определения
A1: Определения: как и кем считается каждый показатель
A4: Показатель | B4: Как считается | C4: Кто отвечает
A5: План продаж | B5: Плановые чистые продажи месяца в розничных ценах, после возвратов, до вычета уценки. | C5: Планировщик
A6: План уценки | B6: Потери от снижения цен за месяц: полная цена минус цена продажи, умноженные на штуки, проданные со скидкой. | C6: Планировщик
A7: План остатка на конец | B7: Остаток в розничных ценах, нужный на конец месяца, обычно запас на несколько следующих недель продаж. | C7: Планировщик
A8: Остаток на начало | B8: Первый месяц: остаток на начало сезона. Следующие месяцы: плановый остаток на конец предыдущего месяца. | C8: Формула
A9: Заказано | B9: Уже размещённые заказы с поставкой в этом месяце, в розничных ценах. | C9: Байер
A10: Open-to-buy | B10: План продаж + план уценки + план остатка на конец − остаток на начало − заказано. | C10: Формула
A11: Маржинальность закупки % | B11: Плановая маржинальность новых закупок: (розничная цена − закупочная цена) ÷ розничная цена, обе без НДС. | C11: Байер и финансы
A12: Open-to-buy по себестоимости | B12: Open-to-buy × (1 − маржинальность закупки %): бюджет, который байер может потратить в закупочных ценах. | C12: Формула
A13: Средняя себестоимость единицы | B13: Средняя закупочная цена единицы новых закупок категории. | C13: Байер
A14: Open-to-buy в штуках | B14: Open-to-buy по себестоимости ÷ средняя себестоимость единицы, округлённо до целых штук. | C14: Формула
A15: Продажи и поставки факт | B15: Данные отчётов по продажам и остаткам за закрытые месяцы, в розничных ценах. | C15: Аналитик
A16: Доля размера и цвета | B16: Очищенные продажи размера или цвета ÷ очищенные продажи категории. | C16: Планировщик
